Workbook

Sheet Assumptions_Control
B2: INSYT CORPORATE — MASTER FINANCIAL & COMMERCIAL MODEL
B3: FAST Standard Compliant · Dynamic Scenario Engine · Working Circularity Breaker
B5: FAST MODELING COLOR CONVENTIONS: | C5: Blue: Hardcoded Inputs | D5: Black: Calculations | E5: Green: Active Check / OK
B7: MODEL SCENARIO SELECTION SWITCH
B8: Active Scenario ID [1=Base, 2=Downside, 3=Upside]: | C8: 1 | D8: =CHOOSE(C8, "CASE 1: BASELINE", "CASE 2: DOWNSIDE (STRESS)", "CASE 3: UPSIDE EXPANSION")
B9: Circularity Breaker Switch [1=Closed Loop Avg Debt, 0=Open Loop Prior Debt]: | C9: 1 | D9: =IF(C9=1, "✔ CLOSED LOOP (Average Debt Balance)", "⚠️ CIRCULARITY BREAKER ON (Beginning Debt)")
B11: KEY COMMERCIAL & OPERATING DRIVERS | C11: Unit | D11: 1. Base Case | E11: 2. Downside | F11: 3. Upside | G11: Active Case
B12: Annual Unit Volume Growth Rate | C12: % | D12: 0.08 | E12: -0.04 | F12: 0.15 | G12: =CHOOSE($C$8, D12, E12, F12)
B13: Baseline Selling Price per Unit (BDT) | C13: BDT | D13: 50 | E13: 46 | F13: 52 | G13: =CHOOSE($C$8, D13, E13, F13)
B14: Direct COGS per Unit (BDT) | C14: BDT | D14: 28 | E14: 30 | F14: 27 | G14: =CHOOSE($C$8, D14, E14, F14)
B15: Trade Spend & Promotion Rate | C15: % | D15: 0.06 | E15: 0.12 | F15: 0.04 | G15: =CHOOSE($C$8, D15, E15, F15)
B16: Freight Absorption per Unit (BDT) | C16: BDT | D16: 2.5 | E16: 4 | F16: 2 | G16: =CHOOSE($C$8, D16, E16, F16)
B17: SG&A Overhead % of Revenue | C17: % | D17: 0.14 | E17: 0.18 | F17: 0.12 | G17: =CHOOSE($C$8, D17, E17, F17)
B18: Accounts Receivable DSO | C18: Days | D18: 45 | E18: 65 | F18: 35 | G18: =CHOOSE($C$8, D18, E18, F18)
B19: Inventory Holding Period (DIO) | C19: Days | D19: 60 | E19: 80 | F19: 50 | G19: =CHOOSE($C$8, D19, E19, F19)
B20: Accounts Payable Period (DPO) | C20: Days | D20: 40 | E20: 30 | F20: 45 | G20: =CHOOSE($C$8, D20, E20, F20)
B21: Annual Maintenance CapEx (BDT M) | C21: BDT M | D21: 35 | E21: 25 | F21: 55 | G21: =CHOOSE($C$8, D21, E21, F21)
B22: Term Debt Interest Rate | C22: % | D22: 0.09 | E22: 0.11 | F22: 0.085 | G22: =CHOOSE($C$8, D22, E22, F22)
B23: Corporate Income Tax Rate | C23: % | D23: 0.275 | E23: 0.275 | F23: 0.275 | G23: =CHOOSE($C$8, D23, E23, F23)

Sheet Three_Statements
B2: INTEGRATED THREE-STATEMENT FINANCIAL MODEL (BDT MILLIONS)
B3: Income Statement · Balance Sheet · Cash Flow Statement with Zero-Plug Balancing Test
B5: Line Item / Period | C5: 2025A | D5: 2026E | E5: 2027E | F5: 2028E | G5: 2029E
B6: 1. INCOME STATEMENT (P&L)
B7: Sales Volume (Million Units) | C7: 8 | D7: =C7 * (1 + Assumptions_Control!$G$12) | E7: =D7 * (1 + Assumptions_Control!$G$12) | F7: =E7 * (1 + Assumptions_Control!$G$12) | G7: =F7 * (1 + Assumptions_Control!$G$12)
B8: Gross Revenue (BDT M) | C8: 400 | D8: =D7 * Assumptions_Control!$G$13 | E8: =E7 * Assumptions_Control!$G$13 | F8: =F7 * Assumptions_Control!$G$13 | G8: =G7 * Assumptions_Control!$G$13
B9: (-) Trade Discounts & Promotional Rebates | C9: 24 | D9: =D8 * Assumptions_Control!$G$15 | E9: =E8 * Assumptions_Control!$G$15 | F9: =F8 * Assumptions_Control!$G$15 | G9: =G8 * Assumptions_Control!$G$15
B10: Net Sales Revenue | C10: =C8 - C9 | D10: =D8 - D9 | E10: =E8 - E9 | F10: =F8 - F9 | G10: =G8 - G9
B11: (-) Cost of Goods Sold (COGS) | C11: 224 | D11: =D7 * Assumptions_Control!$G$14 | E11: =E7 * Assumptions_Control!$G$14 | F11: =F7 * Assumptions_Control!$G$14 | G11: =G7 * Assumptions_Control!$G$14
B12: (-) Freight Absorption & Primary Distribution | C12: 20 | D12: =D7 * Assumptions_Control!$G$16 | E12: =E7 * Assumptions_Control!$G$16 | F12: =F7 * Assumptions_Control!$G$16 | G12: =G7 * Assumptions_Control!$G$16
B13: Gross Commercial Margin | C13: =C10 - C11 - C12 | D13: =D10 - D11 - D12 | E13: =E10 - E11 - E12 | F13: =F10 - F11 - F12 | G13: =G10 - G11 - G12
B14: (-) SG&A Overheads & Operating Expenses | C14: =C10 * Assumptions_Control!$G$17 | D14: =D10 * Assumptions_Control!$G$17 | E14: =E10 * Assumptions_Control!$G$17 | F14: =F10 * Assumptions_Control!$G$17 | G14: =G10 * Assumptions_Control!$G$17
B15: EBITDA | C15: =C13 - C14 | D15: =D13 - D14 | E15: =E13 - E14 | F15: =F13 - F14 | G15: =G13 - G14
B16: (-) Depreciation & Amortization | C16: 18 | D16: 22 | E16: 22 | F16: 22 | G16: 22
B17: Operating Profit (EBIT) | C17: =C15 - C16 | D17: =D15 - D16 | E17: =E15 - E16 | F17: =F15 - F16 | G17: =G15 - G16
B18: (-) Net Interest Expense | C18: 9 | D18: =IF(Assumptions_Control!$G$9=1, AVERAGE(C36, D36), C36) * Assumptions_Control!$G$22 | E18: =IF(Assumptions_Control!$G$9=1, AVERAGE(D36, E36), D36) * Assumptions_Control!$G$22 | F18: =IF(Assumptions_Control!$G$9=1, AVERAGE(E36, F36), E36) * Assumptions_Control!$G$22 | G18: =IF(Assumptions_Control!$G$9=1, AVERAGE(F36, G36), F36) * Assumptions_Control!$G$22
B19: Earnings Before Tax (EBT) | C19: =C17 - C18 | D19: =D17 - D18 | E19: =E17 - E18 | F19: =F17 - F18 | G19: =G17 - G18
B20: (-) Income Tax Expense (27.5%) | C20: =MAX(0, C19 * Assumptions_Control!$G$23) | D20: =MAX(0, D19 * Assumptions_Control!$G$23) | E20: =MAX(0, E19 * Assumptions_Control!$G$23) | F20: =MAX(0, F19 * Assumptions_Control!$G$23) | G20: =MAX(0, G19 * Assumptions_Control!$G$23)
B21: Net Income (PAT) | C21: =C19 - C20 | D21: =D19 - D20 | E21: =E19 - E20 | F21: =F19 - F20 | G21: =G19 - G20
B23: 2. BALANCE SHEET (STATEMENT OF FINANCIAL POSITION)
B24: Cash & Cash Equivalents | C24: 35 | D24: =D55 | E24: =E55 | F24: =F55 | G24: =G55
B25: Accounts Receivable (AR) | C25: 49.3 | D25: =(D10 * Assumptions_Control!$G$18) / 365 | E25: =(E10 * Assumptions_Control!$G$18) / 365 | F25: =(F10 * Assumptions_Control!$G$18) / 365 | G25: =(G10 * Assumptions_Control!$G$18) / 365
B26: Inventories | C26: 36.8 | D26: =(D11 * Assumptions_Control!$G$19) / 365 | E26: =(E11 * Assumptions_Control!$G$19) / 365 | F26: =(F11 * Assumptions_Control!$G$19) / 365 | G26: =(G11 * Assumptions_Control!$G$19) / 365
B27: Total Current Assets | C27: =SUM(C24:C26) | D27: =SUM(D24:D26) | E27: =SUM(E24:E26) | F27: =SUM(F24:F26) | G27: =SUM(G24:G26)
B28: Net Property, Plant & Equipment (PP&E) | C28: 180 | D28: =C28 + Assumptions_Control!$G$21 - D16 | E28: =D28 + Assumptions_Control!$G$21 - E16 | F28: =E28 + Assumptions_Control!$G$21 - F16 | G28: =F28 + Assumptions_Control!$G$21 - G16
B29: TOTAL ASSETS | C29: =C27 + C28 | D29: =D27 + D28 | E29: =E27 + E28 | F29: =F27 + F28 | G29: =G27 + G28
B31: Accounts Payable (AP) | C31: 24.5 | D31: =(D11 * Assumptions_Control!$G$20) / 365 | E31: =(E11 * Assumptions_Control!$G$20) / 365 | F31: =(F11 * Assumptions_Control!$G$20) / 365 | G31: =(G11 * Assumptions_Control!$G$20) / 365
B32: Accrued Operating Liabilities | C32: 12 | D32: =D14 * 0.15 | E32: =E14 * 0.15 | F32: =F14 * 0.15 | G32: =G14 * 0.15
B33: Total Current Liabilities | C33: =SUM(C31:C32) | D33: =SUM(D31:D32) | E33: =SUM(E31:E32) | F33: =SUM(F31:F32) | G33: =SUM(G31:G32)
B34: Long-Term Bank Debt | C34: 100 | D34: =C34 - 15.00 | E34: =D34 - 15.00 | F34: =E34 - 15.00 | G34: =F34 - 15.00
B35: TOTAL LIABILITIES | C35: =C33 + C34 | D35: =D33 + D34 | E35: =E33 + E34 | F35: =F33 + F34 | G35: =G33 + G34
B37: Paid-in Share Capital | C37: 80 | D37: 80 | E37: 80 | F37: 80 | G37: 80
B38: Retained Earnings | C38: 84.6 | D38: =C38 + D21 | E38: =D38 + E21 | F38: =E38 + F21 | G38: =F38 + G21
B39: TOTAL SHAREHOLDERS' EQUITY | C39: =SUM(C37:C38) | D39: =SUM(D37:D38) | E39: =SUM(E37:E38) | F39: =SUM(F37:F38) | G39: =SUM(G37:G38)
B40: TOTAL LIABILITIES & EQUITY | C40: =C35 + C39 | D40: =D35 + D39 | E40: =E35 + E39 | F40: =F35 + F39 | G40: =G35 + G39
B41: ZERO-PLUG BALANCE CHECK (Assets - Liab & Equity) | C41: =IF(ROUND(C29 - C40, 2)=0, "OK 0.00", "OUT OF BALANCE: " & TEXT(C29 - C40, "#,##0.00")) | D41: =IF(ROUND(D29 - D40, 2)=0, "OK 0.00", "OUT OF BALANCE: " & TEXT(D29 - D40, "#,##0.00")) | E41: =IF(ROUND(E29 - E40, 2)=0, "OK 0.00", "OUT OF BALANCE: " & TEXT(E29 - E40, "#,##0.00")) | F41: =IF(ROUND(F29 - F40, 2)=0, "OK 0.00", "OUT OF BALANCE: " & TEXT(F29 - F40, "#,##0.00")) | G41: =IF(ROUND(G29 - G40, 2)=0, "OK 0.00", "OUT OF BALANCE: " & TEXT(G29 - G40, "#,##0.00"))
B43: 3. CASH FLOW STATEMENT (INDIRECT METHOD)
B44: Net Income | D44: =D21 | E44: =E21 | F44: =F21 | G44: =G21
B45: (+) Non-Cash Depreciation & Amortization | D45: =D16 | E45: =E16 | F45: =F16 | G45: =G16
B46: (-/+) Change in Accounts Receivable | D46: =-(D25 - C25) | E46: =-(E25 - D25) | F46: =-(F25 - E25) | G46: =-(G25 - F25)
...

Sheet PVM_Variance_Bridge
B2: PRICE-VOLUME-MIX (PVM) VARIANCE DECOMPOSITION BRIDGE
B3: Exact Zero-Residual Reconciled Waterfall: Price Effect + Volume Effect + Mix Effect
B5: SKU Description | C5: Budget Units | D5: Budget Price | E5: Budget Rev (M) | F5: Actual Units | G5: Actual Price | H5: Actual Rev (M) | I5: Price Effect | J5: Volume Effect | K5: Mix Effect | L5: Total Variance
B6: AquaPure Sparkling 500ml | C6: 4000000 | D6: 35 | E6: =(C6 * D6) / 1000000 | F6: 4800000 | G6: 32.5 | H6: =(F6 * G6) / 1000000 | I6: =(F6 * (G6 - D6)) / 1000000 | J6: =((F6 - C6) * $D$10) / 1000000 | K6: =(F6 * (D6 - $D$10) - (C6 * (D6 - $D$10))) / 1000000 | L6: =H6 - E6
B7: LactoPlus Fortified Milk 1L | C7: 2500000 | D7: 95 | E7: =(C7 * D7) / 1000000 | F7: 2200000 | G7: 94 | H7: =(F7 * G7) / 1000000 | I7: =(F7 * (G7 - D7)) / 1000000 | J7: =((F7 - C7) * $D$10) / 1000000 | K7: =(F7 * (D7 - $D$10) - (C7 * (D7 - $D$10))) / 1000000 | L7: =H7 - E7
B8: NutriCrunch Biscuit 200g | C8: 3000000 | D8: 45 | E8: =(C8 * D8) / 1000000 | F8: 3600000 | G8: 42 | H8: =(F8 * G8) / 1000000 | I8: =(F8 * (G8 - D8)) / 1000000 | J8: =((F8 - C8) * $D$10) / 1000000 | K8: =(F8 * (D8 - $D$10) - (C8 * (D8 - $D$10))) / 1000000 | L8: =H8 - E8
B9: SilkGlow Handwash 250ml | C9: 1200000 | D9: 140 | E9: =(C9 * D9) / 1000000 | F9: 1050000 | G9: 138 | H9: =(F9 * G9) / 1000000 | I9: =(F9 * (G9 - D9)) / 1000000 | J9: =((F9 - C9) * $D$10) / 1000000 | K9: =(F9 * (D9 - $D$10) - (C9 * (D9 - $D$10))) / 1000000 | L9: =H9 - E9
B10: PORTFOLIO TOTAL / RECONCILIATION | C10: =SUM(C6:C9) | D10: =(SUM(E6:E9) * 1000000) / C10 | E10: =SUM(E6:E9) | F10: =SUM(F6:F9) | G10: =(SUM(H6:H9) * 1000000) / F10 | H10: =SUM(H6:H9) | I10: =SUM(I6:I9) | J10: =((F10 - C10) * D10) / 1000000 | K10: =L10 - I10 - J10 | L10: =H10 - E10
B12: EXACT ZERO-RESIDUAL VERIFICATION: | C12: =IF(ROUND((I10 + J10 + K10) - L10, 2)=0, "[OK] 100% PERFECT RECONCILIATION (Residual Error = BDT 0.00)", "[ERROR] VARIANCE LEAKAGE")
